Workbook
Name \a: #REF!
Name \b: #REF!
Name \c: #REF!
Name \d: #REF!
Name \h: #REF!
Name \i: #REF!
Name \l: #REF!
Name \p: #N/A
Name \r: #REF!
Name \s: #REF!
Name \t: #REF!
Name \u: #REF!
Name \v: #REF!
Name \y: #REF!
Name _136_070423_製品系統付け: #REF!
Name _GMT610: [0]!_GMT610
Name _SUB1: #REF!
Name _SUM1: #REF!
Name _SUM2: #REF!
Name A: #REF!
Name aa: [0]!aa
Name AB: #REF!
Name Advertising_Promotions: #REF!
Name after: [0]!after
Name after2: [0]!after2
Name Agreed_Direct: #REF!
Name Agreed_Indirect: #REF!
Name Agreed_Labor: #REF!
Name Agreed_Material: #REF!
Name Agreed_MBFT: #REF!
Name Agreed_Profit: #REF!
Name Agreed_SGA: #REF!
Name Annual_Days: '[7]Machine Data'!$I$6
Name Annual_Uptime: '[7]Machine Data'!$C$18
Name Assembly_Operations: '[7]Machine Rate Data'!$B$8:$B$12
Name Assembly_Time: #REF!
Name B: #REF!
Name Bad_Debt_Expense: #REF!
Name Battery_Cable_Harness: '[7]Material Data'!$AH$9:$AH$18
Name BC: #REF!
Name Benefits: #REF!
Name bf: #REF!
Name BillOfMaterial: '[8]Bill of Mat'!$A$4:$I$61
Name Building: #REF!
Name Building_Maintenance: #REF!
Name Bus._Computer_Equip: #REF!
Name C.I.P.__1: #REF!
Name C.I.P.__2: #REF!
Name C.I.P.__3: #REF!
Name C.I.P.__4: #REF!
Name C.I.P.__5: #REF!
Name C.I.P.__6: #REF!
Name CAPITAL: #REF!
Name CD: #REF!
Name Chart: '[9]Machine Balance'!$C$57
Name CIP_Ideas: #REF!
Name ClearData: [0]!ClearData
Name CLIP: '[7]2005 DGSS Component Prices'!$D$2:$D$1320
Name CNSLD: #REF!
Name CO: #REF!

Sheet 11予算諸元表
A1: 2011年度見積諸元表
A2: １．直接費 一覧
B3: 部門 | D3: 部門コード | E3: 直間比 | F3: ＭＨ単価 | G3: ＭＴ単価 | H3: MPC
B4: AE実装 | D4: UBAE | E4: 1.15 | F4: 2679.4 | G4: 6920.6 | H4: AE作業組
B5: AE後工程 | D5: UBAF | E5: 1.15 | F5: 2679.4 | G5: 1369.5 | H5: AE作業組
B6: AE MT無し | D6: UBM1 | E6: 1.15 | F6: 2679.4 | G6: 0 | H6: AE作業組 | I6: ←設備の無い工程
B7: AH多工程 | D7: UBAH | E7: 1.28 | F7: 2330.1 | G7: 2521.3 | H7: AH作業組
B8: AH単発 | D8: UBAI | E8: 1.28 | F8: 2330.1 | G8: 474.8 | H8: AH作業組
B9: AH MT無し | D9: UBM6 | E9: 1.28 | F9: 2330.1 | G9: 0 | H9: AH作業組 | I9: ←設備の無い工程
B10: AM組立 | D10: UBAM | E10: 1.18 | F10: 2357.1 | G10: 1408.7 | H10: AM作業組
B11: AM MT無し | D11: UBM2 | E11: 1.18 | F11: 2357.1 | G11: 0 | H11: AM作業組 | I11: ←設備の無い工程
B12: AS多工程 | D12: UBAS | E12: 1.37 | F12: 2022.6 | G12: 957.4 | H12: AS作業組
B13: AS MT無し | D13: UBM3 | E13: 1.37 | F13: 2022.6 | G13: 0 | H13: AS作業組 | I13: ←設備の無い工程
B14: JB成形 | D14: UBJB | E14: 1.21 | F14: 2879.5 | G14: 1779.4 | H14: JB作業組
B15: JB MT無し | D15: UBM0 | E15: 1.21 | F15: 2879.5 | G15: 0 | H15: JB作業組 | I15: ←設備の無い工程
B16: JC旧成形 | D16: UBJC | E16: 1.19 | F16: 2390.8 | G16: 1155.6 | H16: JC作業組 | I16: ※見積用 MT単価 (11年標準 1327.2）
B17: JC新成形 | D17: UBJD | E17: 1.19 | F17: 2390.8 | G17: 1264.5 | H17: JC作業組
B18: JP400トンプレス | D18: UBJP | E18: 1.13 | F18: 2608.9 | G18: 5391.7 | H18: JP作業組
B19: JP高速プレス | D19: UBJQ | E19: 1.13 | F19: 2608.9 | G19: 3729.4 | H19: JP作業組 | I19: ※見積用 MT単価 (11年標準 4227.5）
B20: JP積層プレス | D20: UBJR | E20: 1.13 | F20: 2608.9 | G20: 1372.1 | H20: JP作業組
B21: JP MT無し | D21: UBM8 | E21: 1.13 | F21: 2608.9 | G21: 0 | H21: JP作業組 | I21: ←設備の無い工程
B22: JSブロック | D22: UBJS | E22: 1.14 | F22: 1993 | G22: 1537.6 | H22: JS作業組
B23: JSコネクタ二次加工 | D23: UBJU | E23: 1.14 | F23: 1993 | G23: 533.1 | H23: JS作業組
B24: JS MT無し | D24: UBM4 | E24: 1.14 | F24: 1993 | G24: 0 | H24: JS作業組 | I24: ←設備の無い工程
B25: RBラミネート | D25: UBRF | E25: 1.12 | F25: 2761.4 | G25: 1031.7862 | H25: RB作業組 | I25: ※見積用 MT単価 (11年標準 1,311.4)
B26: RB束取 | D26: UBRG | E26: 1.12 | F26: 2761.4 | G26: 2305.7 | H26: RB作業組
B27: RB圧延 | D27: UBRP | E27: 1.12 | F27: 2761.4 | G27: 586.00337 | H27: RB作業組 | I27: ※見積用 MT単価 (11年標準 645.4)
B28: RB MT無し | D28: UBM5 | E28: 1.12 | F28: 2761.4 | G28: 0 | H28: RB作業組 | I28: ←設備の無い工程
B29: RC | D29: UBRC | E29: 1.23 | F29: 2323.4 | G29: 2088.3 | H29: RC作業組
B30: 杉本電装（内作） | D30: UBSD | E30: 1 | F30: 0 | G30: 847.7 | H30: 杉本電装（社内付）
B31: 保田産業（内作） | D31: UBYS | E31: 1 | F31: 0 | G31: 1111.1 | H31: 保田作業（社内付） | I31: ←梱包・選別・コネクタ組立など
B32: 再検査 | D32: UBRI | E32: 1 | F32: 0 | G32: 2319.1 | H32: 古河ライフ | I32: ←SRC再検査工程
B33: ★「MT無し」の工程は、設備などが存在せず、動力料や修繕費の掛からない工程に使用する。
B34: 例) 梱包工程、目視選別工程など
A36: ２．販売直接費 | E36: ※対直原比率
B37: 販売直接費は、下記①～②の合計もしくは個別に見積もった販直費を計上する。
B39: ①工場販直費(国内)
C40: 三重工場から出荷する際の輸送・梱包資材・出荷作業の費用は、下記の比率を用いる。
C41: 輸送費・梱包資材費を別途計上している場合は、2.・3.の比率を用いること.。
E43: 輸送費 | F43: 梱包資材費 | G43: 出荷作業 | H43: 工場販直
...

Sheet 13予算諸元表
A1: 2013年度見積諸元表
A2: １．直接費 一覧
B3: 部門 | D3: 部門コード | E3: 直間比 | F3: ＭＨ単価 | G3: ＭＴ単価 | H3: MPC
B4: AE実装 | D4: UBAE | E4: 1.25 | F4: 2463.8 | G4: 7486.7 | H4: AE作業組
B5: AE後工程 | D5: UBAF | E5: 1.25 | F5: 2463.8 | G5: 3358.7 | H5: AE作業組
B6: AE MT無し | D6: UBM1 | E6: 1.25 | F6: 2463.8 | G6: 0 | H6: AE作業組 | I6: ←設備の無い工程
B7: AH多工程 | D7: UBAH | E7: 1.27 | F7: 2340 | G7: 4101.9 | H7: AH作業組
B8: AH単発 | D8: UBAI | E8: 1.27 | F8: 2340 | G8: 682.9 | H8: AH作業組
B9: AH MT無し | D9: UBM6 | E9: 1.27 | F9: 2340 | G9: 0 | H9: AH作業組 | I9: ←設備の無い工程
B10: AM組立 | D10: UBAM | E10: 1.15 | F10: 2185.1 | G10: 4058.8 | H10: AM作業組
B11: AM MT無し | D11: UBM2 | E11: 1.15 | F11: 2185.1 | G11: 0 | H11: AM作業組 | I11: ←設備の無い工程
B12: AS多工程 | D12: UBAS | E12: 1.72 | F12: 1907.3 | G12: 1168.9 | H12: AS作業組
B13: AS MT無し | D13: UBM3 | E13: 1.72 | F13: 1907.3 | G13: 0 | H13: AS作業組 | I13: ←設備の無い工程
B14: JB成形 | D14: UBJB | E14: 1.15 | F14: 2822.5 | G14: 1641.5 | H14: JB作業組
B15: JB MT無し | D15: UBM0 | E15: 1.15 | F15: 2822.5 | G15: 0 | H15: JB作業組 | I15: ←設備の無い工程
B16: JC旧成形 | D16: UBJC | E16: 1.14 | F16: 2338.6 | G16: 1300.6 | H16: JC作業組
B17: JC新成形 | D17: UBJD | E17: 1.14 | F17: 2338.6 | G17: 1178.5 | H17: JC作業組
B18: JC MT無し | D18: UBM7 | E18: 1.14 | F18: 2338.6 | G18: 0 | H18: JC作業組 | I18: ←設備の無い工程
B19: JP400トンプレス | D19: UBJP | E19: 1.13 | F19: 3027.4 | G19: 4118 | H19: JP作業組
B20: JP高速プレス | D20: UBJQ | E20: 1.13 | F20: 3027.4 | G20: 3965.2 | H20: JP作業組
B21: JSブロック | D21: UBJS | E21: 1.22 | F21: 2447.8 | G21: 1474 | H21: JS作業組
B22: JSコネクタ二次加工 | D22: UBJU | E22: 1.22 | F22: 2447.8 | G22: 512.5 | H22: JS作業組
B23: JS MT無し | D23: UBM4 | E23: 1.22 | F23: 2447.8 | G23: 0 | H23: JS作業組 | I23: ←設備の無い工程
B24: RBラミネート | D24: UBRF | E24: 1.09 | F24: 2424.1 | G24: 938.9 | H24: RB作業組
B25: RB束取 | D25: UBRG | E25: 1.09 | F25: 2424.1 | G25: 1690.5 | H25: RB作業組
B26: RB圧延 | D26: UBRP | E26: 1.09 | F26: 2424.1 | G26: 885 | H26: RB作業組
B27: RB MT無し | D27: UBM5 | E27: 1.09 | F27: 2424.1 | G27: 0 | H27: RB作業組 | I27: ←設備の無い工程
B28: RC | D28: UBRC | E28: 1.23 | F28: 2350.1 | G28: 3641.4 | H28: RC作業組
B29: 杉本電装（内作） | D29: UBSD | E29: 1 | F29: 0 | G29: 1498.4 | H29: 杉本電装（社内付）
B30: 保田産業（内作） | D30: UBYS | E30: 1 | F30: 0 | G30: 1718.1 | H30: 保田作業（社内付） | I30: ←梱包・選別・コネクタ組立など
B31: 桑名作業 | D31: UBRK | E31: 1 | H31: 桑名B/C | I31: ←BUSハーネス/SRC検査
B32: 再検査 | D32: UBRI | E32: 1 | F32: 0 | G32: 5888.6 | H32: 古河ライフ | I32: ←桑名へ移管
B33: ★「MT無し」の工程は、設備などが存在せず、動力料や修繕費の掛からない工程に使用する。
B34: 例) 梱包工程、目視選別工程など
A36: ２．販売直接費 | E36: ※対直原比率
B37: 販売直接費は、下記①～②の合計もしくは個別に見積もった販直費を計上する。
B39: ①工場販直費(国内)
C40: 三重工場から出荷する際の輸送・梱包資材・出荷作業の費用は、下記の比率を用いる。
C41: 輸送費・梱包資材費を別途計上している場合は、2.・3.の比率を用いること.。
E43: 輸送費 | F43: 梱包資材費 | G43: 出荷作業 | H43: 工場販直
...

Sheet Sheet1
A1: 11年度 購入品標準原価 | F1: ※１ 購入単位あたり | G1: ※2 購入単位 = 単位換算 × BOM単位 （例： kg = 1000 × g)
A2: 品番 | B2: 品名 | C2: 購入先 | D2: 分類CD | E2: 購入単位 | F2: 標準単価 ※1 | G2: 単位換算 ※2 | H2: BOM単位 | I2: 大分類 | J2: 中分類 | K2: 小分類
A3: Q011749000-M00 | B3: 1013NW8(OUT) | C3: 古河産業株式会社 | D3: TA0 | E3: kg | F3: 355 | G3: 1000 | H3: g | I3: RESIN | J3: PA6 | K3: PA6
A4: T100111000-M00 | B4: 4359GN[NATURAL] | C4: 出光ライオンコンポジット株式会社 | D4: TA0 | E4: kg | F4: 325 | G4: 1000 | H4: g | I4: RESIN | J4: PP | K4: PP
A5: C010006000-M00 | B5: 446BU<KS>(BLUE)(RECEIVE) | C5: 古河産業株式会社 | D5: TA0 | E5: kg | F5: 1445 | G5: 1000 | H5: g | I5: COLOR RESIN | J5: MIE LOCAL | K5: MIE LOCAL
A6: N050004000-M20 | B6: 459YL<KS>(YELLOW)[J-JH] | C6: 古河産業株式会社 | D6: TA0 | E6: kg | F6: 1605 | G6: 1000 | H6: g | I6: RESIN | J6: COLOR BATCH | K6: COLOR BATCH
A7: P010163000-M00 | B7: 4600G-5(IN) | C7: 長瀬産業株式会社 | D7: TA0 | E7: kg | F7: 217.05 | G7: 1000 | H7: g | I7: RESIN | J7: PP | K7: PP
A8: P010163000-M70 | B8: 4600G-5(K9624) | C8: 長瀬産業株式会社 | D8: TA0 | E8: kg | F8: 217.05 | G8: 1000 | H8: g | I8: RESIN | J8: PP | K8: PP
A9: P010163000-M10 | B9: 4600G-5(OUT) | C9: 長瀬産業株式会社 | D9: TA0 | E9: kg | F9: 217.05 | G9: 1000 | H9: g | I9: RESIN | J9: PP | K9: PP
A10: P010163000-M50 | B10: 4600G-5(V-9031)(OUT) | C10: 長瀬産業株式会社 | D10: TA0 | E10: kg | F10: 217.05 | G10: 1000 | H10: g | I10: RESIN | J10: PP | K10: PP
A11: P010163000-M60 | B11: 4600G-5(V-9031)[J-FN] | C11: 長瀬産業株式会社 | D11: TA0 | E11: kg | F11: 217.05 | G11: 1000 | H11: g | I11: RESIN | J11: PP | K11: PP
A12: P010163000-M40 | B12: 4600G-5(V-9301)(IN) | C12: 長瀬産業株式会社 | D12: TA0 | E12: kg | F12: 217.05 | G12: 1000 | H12: g | I12: RESIN | J12: PP | K12: PP
A13: C010004000-M10 | B13: 464GN(KS)ﾐﾄﾞﾘ ﾐｴ(OUT) | C13: 古河産業株式会社 | D13: TA0 | E13: kg | F13: 1535 | G13: 1000 | H13: g | I13: COLOR RESIN | J13: MIE LOCAL | K13: MIE LOCAL
A14: C010004000-M00 | B14: 464GN(KS)ﾐﾄﾞﾘ ﾐｴ(RECEIVE) | C14: 古河産業株式会社 | D14: TA0 | E14: kg | F14: 1525 | G14: 1000 | H14: g | I14: COLOR RESIN | J14: MIE LOCAL | K14: MIE LOCAL
... A292: C030976000-M00 | B292: ﾚﾏﾛｲ(ﾌﾝｻｲ)ﾎｳｴｲ | C292: 宝永プラスチックス株式会社 | D292: TD0 | E292: kg | F292: 50 | G292: 1 | H292: kg | I292: MIE LOCAL | J292: MIE LOCAL | K292: MIE LOCAL

Sheet Sheet1 (2)
K1: CP-130278 別紙-1
A2: 030B向け検討コネクタ一覧
A5: 種類 | B5: 親番号 | C5: F/M | D5: assy名称（仮） | E5: 子番号 | F5: 構成部品 | G5: 部品名称（仮） | H5: 体積 mm3 | I5: 質量 ※2 g | J5: 材質 | K5: DWG No.
A7: 0.64Ⅱ-22P | B7: ① | C7: F | D7: XFSG-C-22F | E7: ①-1 | F7: HSG | G7: XFSG-E-22F | H7: 3418.5 | I7: 4.478 | J7: PBT B1305 | K7: XFSG-P-EF22-1
E8: ①-2 | F8: ﾘﾃｰﾅ | G8: XFSG-L-22N ※1 | H8: 386.3 | I8: 0.506 | J8: PBT B1305 | K8: XFSG-P-LN22-1
B9: ② | C9: M | D9: XFSG-C-22M | E9: ②-1 | F9: HSG | G9: XFSG-E-22M | H9: 5585.2 | I9: 7.317 | J9: PBT B1305 | K9: XFSG-P-EM22-1
E10: ②-2 | F10: ﾘﾃｰﾅ | G10: XFSG-L-22N ※1 | H10: 386.3 | I10: 0.506 | J10: PBT B1305 | K10: XFSG-P-LN22-1
A11: 0.64Ⅱ-10P+1.5-8P | B11: ③ | C11: F | D11: XFSG/FMG8-C-B18F | E11: ③-1 | F11: HSG | G11: XFSG/FMG8-E-B18F | H11: 3279.1 | I11: 4.296 | J11: PBT B1305 | K11: XFSFM-P-EF0818B-1
E12: ③-2 | F12: ﾘﾃｰﾅ | G12: XFSG/FMG8-L-B18F | H12: 365.3 | I12: 0.478 | J12: PBT B1305 | K12: XFSFM-P-LF0818B-1
B13: ④ | C13: M | D13: XFSG/FMG8-C-B18M | E13: ④-1 | F13: HSG | G13: XFSG/FMG8-E-B18M | H13: 6433.1 | I13: 8.427 | J13: PBT B1305 | K13: XFSFM-P-EM0818B-1
E14: ④-2 | F14: ﾘﾃｰﾅ | G14: XFSG/FMG8-L-B18M | H14: 398.8 | I14: 0.522 | J14: PBT B1305 | K14: XFSFM-P-LM0818B-1
A16: ※1 XFSG-L-22N は同一部品
A17: ※2 B1305 密度1310kg/m3 で計算

Sheet Sheet5
A1: 親番号 | B1: トヨタ品番 | C1: 720A使用数量/台 | D1: コネクタメーカー | E1: 12下期管理自給価格 | F1: 目標コスト（管理費込み） | G1: 720A償却個数（生涯）
A2: ① | B2: 90980-12372 | C2: 2 | D2: 住友電装 | E2: 11.1 | F2: =+E2*1.03 -> 11.433 | G2: =+C2*2025*12*6 -> 291600
A3: ② | B3: 90980-12371 | C3: 2 | D3: 住友電装 | E3: 14.2 | F3: =+E3*1.03 -> 14.626 | G3: =+C3*2025*12*6 -> 291600
A4: ③ | B4: 90980-12741 | C4: 2 | D4: 住友電装 | E4: 10.9 | F4: =+E4*1.03 -> 11.227 | G4: =+C4*2025*12*6 -> 291600
A5: ④ | B5: 90980-12740 | C5: 2 | D5: 住友電装 | E5: 13.6 | F5: =+E5*1.03 -> 14.008 | G5: =+C5*2025*12*6 -> 291600
A6: ⑤ | B6: 90980-12771 | C6: 4 | D6: 矢崎総業 | E6: 21.9 | F6: =+E6*1.03 -> 22.557 | G6: =+C6*2025*12*6 -> 583200
A7: ⑥ | B7: 90980-12770 | C7: 4 | D7: 矢崎総業 | E7: 24.3 | F7: =+E7*1.03 -> 25.029 | G7: =+C7*2025*12*6 -> 583200
A8: ⑦ | B8: 90980-12737 | C8: 1 | D8: 住友電装 | E8: 9.9 | F8: =+E8*1.03 -> 10.197 | G8: =+C8*2025*12*6 -> 145800
A9: ⑧ | B9: 90980-12736 | C9: 1 | D9: 住友電装 | E9: 11.7 | F9: =+E9*1.03 -> 12.051 | G9: =+C9*2025*12*6 -> 145800
A10: ⑨ | B10: 90980-12937 | C10: 1 | D10: 住友電装 | E10: 6.9 | F10: =+E10*1.03 -> 7.107 | G10: =+C10*2025*12*6 -> 145800
A11: ⑩ | B11: 90980-12936 | C11: 1 | D11: 住友電装 | E11: 8.4 | F11: =+E11*1.03 -> 8.652 | G11: =+C11*2025*12*6 -> 145800
A12: ⑪ | B12: 90980-12366 | C12: 1 | D12: 住友電装 | E12: 7.4 | F12: =+E12*1.03 -> 7.622 | G12: =+C12*2025*12*6 -> 145800
A13: ⑫ | B13: 90980-12365 | C13: 1 | D13: 住友電装 | E13: 8.8 | F13: =+E13*1.03 -> 9.064 | G13: =+C13*2025*12*6 -> 145800
... A15: ⑭ | B15: 90980-12807 | C15: 2 | D15: 住友電装 | E15: 9.3 | F15: =+E15*1.03 -> 9.579 | G15: =+C15*2025*12*6 -> 291600
B16: ※企画台数2,025台/月、6年モデルで算出
B17: ※目標コスト：最低限これ以下にしないといけないという数字

Sheet RESIN
A1: 10年度 購入品標準原価 | F1: ※１ 購入単位あたり | G1: ※2 購入単位 = 単位換算 × BOM単位 （例： kg = 1000 × g)
A2: 品番 | B2: 品名 | C2: 購入先 | D2: 分類CD | E2: 購入単位 | F2: 標準単価 ※1 | G2: 単位換算 ※2 | H2: BOM単位 | I2: 大分類 | J2: 中分類 | K2: 小分類
A3: Q011749000-M00 | B3: 1013NW8(OUT) | C3: 古河産業株式会社 | D3: TA0 | E3: kg | F3: 385 | G3: 1000 | H3: g | I3: RESIN | J3: PA6 | K3: PA6
A4: N050004000-M20 | B4: 459YL<KS>(YELLOW)[J-JH] | C4: 古河産業株式会社 | D4: TA0 | E4: kg | F4: 1605 | G4: 1000 | H4: g | I4: RESIN | J4: COLOR BATCH | K4: COLOR BATCH
A5: P010163000-M00 | B5: 4600G-5(IN) | C5: 長瀬産業株式会社 | D5: TA0 | E5: kg | F5: 209.55 | G5: 1000 | H5: g | I5: RESIN | J5: PP | K5: PP
A6: P010163000-M70 | B6: 4600G-5(K9624) | C6: 長瀬産業株式会社 | D6: TA0 | E6: kg | F6: 209.55 | G6: 1000 | H6: g | I6: RESIN | J6: PP | K6: PP
A7: P010163000-M10 | B7: 4600G-5(OUT) | C7: 長瀬産業株式会社 | D7: TA0 | E7: kg | F7: 209.55 | G7: 1000 | H7: g | I7: RESIN | J7: PP | K7: PP
A8: P010163000-M50 | B8: 4600G-5(V-9031)(OUT) | C8: 長瀬産業株式会社 | D8: TA0 | E8: kg | F8: 209.55 | G8: 1000 | H8: g | I8: RESIN | J8: PP | K8: PP
A9: P010163000-M60 | B9: 4600G-5(V-9031)[J-FN] | C9: 長瀬産業株式会社 | D9: TA0 | E9: kg | F9: 209.55 | G9: 1000 | H9: g | I9: RESIN | J9: PP | K9: PP
A10: P010163000-M40 | B10: 4600G-5(V-9301)(IN) | C10: 長瀬産業株式会社 | D10: TA0 | E10: kg | F10: 209.55 | G10: 1000 | H10: g | I10: RESIN | J10: PP | K10: PP
A11: P010164000-M00 | B11: 4704G | C11: 長瀬産業株式会社 | D11: TA0 | E11: kg | F11: 220.35 | G11: 1000 | H11: g | I11: RESIN | J11: PP | K11: PP
A12: R010410000-M10 | B12: CJ936N(J) | C12: 古河産業株式会社 | D12: TA0 | E12: kg | F12: 273 | G12: 1000 | H12: g | I12: RESIN | J12: PP | K12: PP
A13: R010410000-M00 | B13: CJ936N(OUT) [I] | C13: ＩＣＴＣ | D13: UG0 | E13: kg | F13: 89.04 | G13: 1000 | H13: g | I13: RESIN | J13: PP | K13: PP
A14: P030045000-M00 | B14: DELRIN 900P8(BLACK) | C14: ＣＢＣ株式会社 | D14: TA0 | E14: kg | F14: 225 | G14: 1000 | H14: g | I14: RESIN | J14: POM | K14: POM
... A207: C010042000-M00 | B207: ﾅｲﾛﾝｶﾗ- K 37-100(IN) | C207: 三井物産株式会社 | D207: TA0 | E207: kg | F207: 3050 | G207: 1000 | H207: g | I207: COLOR RESIN | J207: MIE LOCAL | K207: MIE LOCAL

Sheet 予算諸元表
A1: 09予算諸元表
B2: 諸元（部門）
C3: 部門 | E3: 部門コード | F3: 直間比 | G3: ＭＨ単価 | H3: ＭＴ単価 | I3: MPC
C4: AE実装 | E4: UBAE | F4: 1.21 | G4: 2225.9 | H4: 6900 | I4: AE作業組
C5: AE後工程 | E5: UBAF | F5: 1.21 | G5: 2225.9 | H5: 890.1 | I5: AE作業組
C6: AE MT無し | E6: UBM1 | F6: 1.21 | G6: 2225.9 | H6: 0 | I6: AE作業組 | J6: ←設備の無い工程
C7: AH多工程 | E7: UBAH | F7: 1.28 | G7: 2191.5 | H7: 2924.9 | I7: AH作業組
C8: AH単発 | E8: UBAI | F8: 1.28 | G8: 2191.5 | H8: 856.1 | I8: AH作業組
C9: AH MT0 | E9: UBM6 | F9: 1.28 | G9: 2191.5 | H9: 0 | I9: AH作業組 | J9: ←設備の無い工程
C10: AM組立 | E10: UBAM | F10: 1.18 | G10: 2169.2 | H10: 1128.5 | I10: AM作業組
C11: AM MT無し | E11: UBM2 | F11: 1.18 | G11: 2169.2 | H11: 0 | I11: AM作業組 | J11: ←設備の無い工程
C12: AS多工程 | E12: UBAS | F12: 1.7 | G12: 2228.9 | H12: 1083.7 | I12: AS作業組
C13: AS単発 | E13: UBAT | F13: 1.7 | G13: 2228.9 | H13: 1083.7 | I13: AS作業組
C14: AS MT無し | E14: UBM3 | F14: 1.7 | G14: 2228.9 | H14: 0 | I14: AS作業組 | J14: ←設備の無い工程
C15: JB成形 | E15: UBJB | F15: 1.18 | G15: 2901.5 | H15: 2076.7 | I15: JB作業組
C16: JB MT無し | E16: UBM0 | F16: 1.18 | G16: 2901.5 | H16: 0 | I16: JB作業組 | J16: ←設備の無い工程
C17: JC旧成形 | E17: UBJC | F17: 1.22 | G17: 2726.7 | H17: 1268.5 | I17: JC作業組
C18: JC新成形 | E18: UBJD | F18: 1.22 | G18: 2726.7 | H18: 1450.2 | I18: JC作業組
C19: JP400トンプレス | E19: UBJP | F19: 1.13 | G19: 2469.7 | H19: 5253.5 | I19: JP作業組
C20: JP高速プレス | E20: UBJQ | F20: 1.13 | G20: 2469.7 | H20: 3855.9 | I20: JP作業組
C21: JP積層プレス | E21: UBJR | F21: 1.13 | G21: 2469.7 | H21: 1850 | I21: JP作業組
C22: JSブロック | E22: UBJS | F22: 1.13 | G22: 1908.5 | H22: 2360.6 | I22: JS作業組
C23: JSコネクタ二次加工 | E23: UBJU | F23: 1.13 | G23: 1908.5 | H23: 362.6 | I23: JS作業組
C24: JS MT無し | E24: UBM4 | F24: 1.13 | G24: 1908.5 | H24: 0 | I24: JS作業組 | J24: ←設備の無い工程
C25: RBラミネート | E25: UBRF | F25: 1.14 | G25: 2397.9 | H25: 921.9 | I25: RB作業組
C26: RB束取 | E26: UBRG | F26: 1.14 | G26: 2397.9 | H26: 1549 | I26: RB作業組
C27: RB圧延 | E27: UBRP | F27: 1.14 | G27: 2397.9 | H27: 296.8 | I27: RB作業組
C28: RB MT無し | E28: UBM5 | F28: 1.14 | G28: 2397.9 | H28: 0 | I28: RB作業組 | J28: ←設備の無い工程
C29: RC | E29: UBRC | F29: 1.17 | G29: 1934.4 | H29: 1211.2 | I29: RC作業組
C30: 杉本電装（内作） | E30: UBSD | F30: 1 | G30: 0 | H30: 1793.3 | I30: 杉本電装（社内付）
C31: 保田産業（内作） | E31: UBYS | F31: 1 | G31: 0 | H31: 1636.6 | I31: 保田作業（社内付） | J31: ←梱包・選別・コネクタ組立など
C32: 再検査 | E32: UBRI | F32: 1 | G32: 0 | H32: 2662.2 | I32: 古河ライフ | J32: ←SRC再検査工程
B34: 諸元（間接費） ※全て対直原比率
C36: 間接費は、０8年の製品系統別PL予算より下記の値を用いる。
E37: ブロック | F37: ＳＲＣ | G37: コネクタ | H37: 電子部品※ | I37: センサー | J37: スマコネ | K37: アンテナ
C38: 工場間接費 | E38: 0.12048982 | F38: 0.11182968 | G38: 0.14694502 | H38: 0.11740127 | I38: 0.12043097 | J38: 0.07442975 | K38: 0.16410439
C39: 一般管理費 | E39: 0.091156534 | F39: 0.1086448 | G39: 0.15014259 | H39: 0.095504871 | I39: 0.083369917 | J39: 0.065985262 | K39: 0.14690259
C40: 営業外 | E40: 0.0028491943 | F40: 0.0028491943 | G40: 0.0028491943 | H40: 0.0028491943 | I40: 0.0028491943 | J40: 0.0028491943 | K40: 0.0028491943
E41: =SUM(E38:E40) -> 0.21449555 | F41: =SUM(F38:F40) -> 0.22332368 | G41: =SUM(G38:G40) -> 0.29993681 | H41: =SUM(H38:H40) -> 0.21575533 | I41: =SUM(I38:I40) -> 0.20665008 | J41: =SUM(J38:J40) -> 0.14326421 | K41: =SUM(K38:K40) -> 0.31385617
E42: (工場間接費は専用設備の償却費を除く｡) | I42: ※電装工場平均値
...

Sheet Cost Table
B1: INJECTION PARTS | AW1: 間接費 13予算(FAS三重工場出荷品) | BA1: /海外工場出荷品(三重工場売上なし)提示なし | BF1: ※対直原比率 | BJ1: 営業販直費 13予算 | BP1: 工場販直費 13予算 ※対直原比率(三重工場から出荷する際）
U2: MT/MH | AX2: 工場 間接費 | AY2: 一般 管理費 | AZ2: 電工 本社費 | BB2: 工場 間接費 | BC2: 一般 管理費 | BD2: 電工 本社費 | BF2: 工場間接 | BG2: 一般管理 | BH2: 販直率 | BJ2: 行き先 | BK2: 輸送費 | BM2: 行き先 | BN2: 輸送費 | BS2: 輸送費 | BT2: 梱包費 | BU2: 出荷作業 | BV2: 工場販直
B3: quotation No. | U3: Process No. | V3: Process Name | AA3: Assign /machine | AB3: OA | AE3: Ratio Indirect-Direct/Direct | AF3: MH等価単価 | AG3: MT等価単価 | AH3: MH Charge | AI3: MT Charge | AJ3: Amortization | BK3: 込み | BL3: 別 | BN3: 込み | BO3: 別 | BP3: 1.全て直原比率で算出 | BS3: 0.0075 | BT3: 0.0077 | BU3: 0.0075 | BV3: 0.0227 | BW3: 1
B4: FOREX ( 1 PHP= ) | E4: 2.2 | L4: Resin | O4: FEAP | P4: FEAPsup | Q4: EPMI | AW4: ブロック | AX4: 0.042 | AY4: 0.0639 | AZ4: 0 | BB4: 0.0244 | BC4: 0.0823 | BD4: 0 | BE4: FURMEX | BF4: 0.138 | BG4: 0.128 | BH4: 0.016 | BI4: 対直原 | BJ4: SC経由なし | BK4: 0 | BM4: いすゞ | BN4: 0.0454 | BO4: - | BP4: 2.輸送費を別途計上 | BS4: 0 | BT4: 0.0077 | BU4: 0.0075 | BV4: 0.0153 | BW4: 2
B5: FOREX ( 1 USD= ) | E5: 105 | H5: SPS | L5: XAREX | U5: a | V5: FEAP Horizontal | AH5: =MTMH!E15 -> 297.65682 | AI5: =MTMH!E16 -> 543.66751 | AW5: SRC | AX5: 0.1369 | AY5: 0.1243 | AZ5: 0 | BB5: 0.0477 | BC5: 0.0732 | BD5: 0 | BE5: FACE | BF5: 0.128 | BG5: 0.082 | BH5: 0.065 | BI5: 対直原 | BJ5: マツダ | BK5: 0.007 | BM5: FEAP | BN5: 別途見積 | BO5: 0 | BP5: 3.輸送費・梱包費資材費を別途計上 | BS5: 0 | BT5: 0 | BU5: 0.0075 | BV5: =SUM(BS5:BU5) -> 0.0075 | BW5: 3 | CG5: For Horizontal Injection Process MT is Jpy 423
B6: Interest Rate (Annual) | E6: 0.02 | H6: PBT | L6: BASF B4520 Q120 | O6: ='Resin Recycle'!I5 -> 304.5 | U6: b | V6: FEAP Vertical | AH6: =AH5*2 -> 595.31365 | AI6: =MTMH!E17 -> 681.92075 | AW6: コネクタ | AX6: 0.1344 | AY6: 0.1025 | AZ6: 0 | BB6: 0.10454678 | BC6: 0.1397124 | BD6: 0 | BE6: FAST | BF6: 0.069 | BG6: 0.0766 | BH6: 0.058 | BI6: 対直原 | BJ6: ダイハツ | BK6: 0.0073 | BM6: FENA | BN6: 別途見積 | BO6: 0 | CG6: MH is Jpy 177
B7: Payment Term (months) | E7: 24 | H7: POM | L7: MEP F30-03 | O7: ='Resin Recycle'!I7 -> 207.9 | U7: c | V7: Off Line Work | AW7: 電子部品 | AX7: 0.071 | AY7: 0.0669 | AZ7: 0 | BB7: 0.0333 | BC7: 0.0822 | BD7: 0 | BE7: FEAP | BF7: 0.17 | BG7: 0.038 | BH7: 0.029 | BI7: 対直原 | BJ7: ホンダ鈴鹿 | BK7: 0.0145 | BM7: FESZ | BN7: 別途見積 | BO7: 0
B8: Start to Investment | E8: - | H8: POM | L8: MEP F30-73R1 | O8: ='Resin Recycle'!F8 -> 345.5 | U8: d | V8: BSS Vertical | BE8: FESZ | BF8: 0.092 | BG8: 0.057 | BH8: 0.042 | BI8: 対直原 | BJ8: ホンダ狭山 | BK8: 0.0145 | BM8: FAST | BN8: 別途見積 | BO8: 0
B9: Start to mass prod. | E9: - | H9: POM | L9: MEP FX-11J | O9: ='Resin Recycle'!I10 -> 417.9 | U9: e | AW9: スマコネ | AX9: 0.0404 | AY9: 0.0697 | AZ9: 0 | BB9: 0.0198 | BC9: 0.0748 | BD9: 0 | BE9: 津河 | BF9: 0.1 | BG9: 0.07 | BH9: 0.02 | BI9: 対直原 | BJ9: トヨタ | BK9: 0.0098 | BM9: FACE | BN9: 別途見積 | BO9: 0
B10: Operetion Hour (Hr/Day) | E10: 24 | H10: PPS | L10: DIC FZ-1140K | O10: ='Resin Recycle'!F23 -> 736.5 | U10: f | BB10: 0.0472 | BC10: 0 | BD10: 0 | BE10: FAPV | BF10: 0.1735 | BG10: 0.0776 | BI10: 対加工費 | BJ10: スズキ・ヤマハ | BK10: 0.0169 | BM10: 津河 | BN10: 別途見積 | BO10: 0
B11: Operational Availability(%) | E11: 0.95 | H11: PPS | L11: DIC FZ-1040K | O11: ='Resin Recycle'!F24 -> 776.9 | U11: g | AW11: 営業外 | AX11: 0.0028 | BE11: ※1減価償却費含む | BJ11: 富士重 | BK11: 0.0169 | BN11: ※海外輸送費は, 各拠点毎のﾌｫ-ﾏｯﾄで算出の事。
B13: Injection Molding Parts, Direct Cost
B14: QuotationNo. | C14: Process No. | E14: Process Name | H14: Demand | I14: Ave.Days | J14: Daily | K14: Lot Size | M14: Loss Rate | P14: Resin Name | S14: # Of Cavity | T14: Single Shot Inf. | X14: Production Lot | Z14: Resin | AA14: Recycle | AB14: Recycle | AC14: Disposal | AE14: Material Cost (JPY/pcs) | AF14: Cycle Time (sec) | AG14: Process Cost | AL14: Purge Loss | AN14: Prod. loss (defect) | AQ14: Operational Availability
H15: Ave. | I15: / Month | J15: Demand | M15: Purge (%) | N15: Disposal (%) | O15: Defect (%) | T15: Parts | U15: Runner | V15: Consum- | X15: Prdn | Y15: Consum- | Z15: Cost | AA15: Ratio | AB15: Cost | AC15: Cost | AG15: Man/Machine | AI15: PC | AN15: Intial | AO15: QC | AP15: Total | AQ15: change | AR15: OA (%)
V16: ption | X16: Shots | Y16: ption | AG16: Charge Rate (JPY/H) | AN16: Disposal | AO16: Sample | AQ16: model
H17: pcs/M | I17: Y2020 | K17: (Pcs/time) | P17: Polymer | Q17: Grade | T17: g/pc | U17: g/shot | V17: g/shot | X17: shots/Lot | Y17: g/pc | Z17: JPY/Kg | AA17: % | AB17: JPY/Kg | AC17: JPY/Kg | AD17: JPY/pc | AG17: MH | AH17: MT | AI17: （JPY/pc） | AL17: g/Lot | AM17: Shots/Lot | AN17: Shots/Lot | AO17: Shots/Lot | AP17: g/Lot | AQ17: min
B18: 1 | C18: a | D18: TMR-050 | E18: ROTAOTR | K18: 20000 | M18: =AM18*S18/K18 -> 0.0012578616 | N18: =(AN18+AO18)*S18/K18 -> 0.0018 | O18: 0.0002 | P18: POM | Q18: FX-11J | S18: 2 | T18: 31.6 | U18: 16.3 | V18: =T18*S18+U18 -> 79.5 | X18: =ROUNDUP((K18/(1-O18)+AN18+AO18)/S18,0) -> 10012 | Y18: =(X18*V18+AL18)/K18 -> 39.8477 | Z18: 437.8 | AA18: 0 | AB18: ='Resin Recycle'!$O$48 -> 57.114983 | AC18: =IF(AA18=0,'Resin Recycle'!$F$40,0) -> 17.6 | AD18: =(Y18-T18)*AC18/1000 -> 0.14515952 | AE18: =Y18*(1-AA18)*Z18/1000+Y18*AA18*AB18/1000+AD18 -> 17.590483 | AF18: 30 | AG18: =AH$5 -> 297.65682 | AH18: =AI$5 -> 543.66751 | AI18: =ROUNDUP(AF18/S18*(AH18+AG18)/(1-N18-O18)/3600,2) -> 3.52 | AL18: 1000 | AM18: =AL18/V18 -> 12.578616 | AN18: 15 | AO18: 3 | AP18: =(AN18+AO18)*V18 -> 1431 | AQ18: 30 | AR18: =IF(C18<1," ",(K18*AF18/S18)/(AQ18*60+K18*AF18/S18)) -> 0.99403579
B19: 2 | C19: a | D19: TMR-051 | E19: STATOR | K19: 20000 | M19: =AM19*S19/K19 -> 0.0012578616 | N19: =(AN19+AO19)*S19/K19 -> 0.0018 | O19: 0.0002 | P19: PBT | Q19: BASF B4520 Q120 | S19: 2 | T19: 31.6 | U19: 16.3 | V19: =T19*S19+U19 -> 79.5 | X19: =ROUNDUP((K19/(1-O19)+AN19+AO19)/S19,0) -> 10012 | Y19: =(X19*V19+AL19)/K19 -> 39.8477 | Z19: 437.8 | AA19: 0 | AB19: ='Resin Recycle'!$O$48 -> 57.114983 | AC19: =IF(AA19=0,'Resin Recycle'!$F$40,0) -> 17.6 | AD19: =(Y19-T19)*AC19/1000 -> 0.14515952 | AE19: =Y19*(1-AA19)*Z19/1000+Y19*AA19*AB19/1000+AD19 -> 17.590483 | AF19: 30 | AG19: =AH$5 -> 297.65682 | AH19: =AI$5 -> 543.66751 | AI19: =ROUNDUP(AF19/S19*(AH19+AG19)/(1-N19-O19)/3600,2) -> 3.52 | AL19: 1000 | AM19: =AL19/V19 -> 12.578616 | AN19: 15 | AO19: 3 | AP19: =(AN19+AO19)*V19 -> 1431 | AQ19: 30 | AR19: =IF(C19<1," ",(K19*AF19/S19)/(AQ19*60+K19*AF19/S19)) -> 0.99403579
B20: 3 | C20: a | D20: TMR-051 | E20: SUBSTATOR | K20: 20000 | M20: =AM20*S20/K20 -> 0.0012578616 | N20: =(AN20+AO20)*S20/K20 -> 0.0018 | O20: 0.0002 | P20: PPE+PA | Q20: C82HL | S20: 2 | T20: 31.6 | U20: 16.3 | V20: =T20*S20+U20 -> 79.5 | X20: =ROUNDUP((K20/(1-O20)+AN20+AO20)/S20,0) -> 10012 | Y20: =(X20*V20+AL20)/K20 -> 39.8477 | Z20: 437.8 | AA20: 0 | AB20: ='Resin Recycle'!$O$48 -> 57.114983 | AC20: =IF(AA20=0,'Resin Recycle'!$F$40,0) -> 17.6 | AD20: =(Y20-T20)*AC20/1000 -> 0.14515952 | AE20: =Y20*(1-AA20)*Z20/1000+Y20*AA20*AB20/1000+AD20 -> 17.590483 | AF20: 29 | AG20: =AH$5 -> 297.65682 | AH20: =AI$5 -> 543.66751 | AI20: =ROUNDUP(AF20/S20*(AH20+AG20)/(1-N20-O20)/3600,2) -> 3.4 | AL20: 1000 | AM20: =AL20/V20 -> 12.578616 | AN20: 15 | AO20: 3 | AP20: =(AN20+AO20)*V20 -> 1431 | AQ20: 30 | AR20: =IF(C20<1," ",(K20*AF20/S20)/(AQ20*60+K20*AF20/S20)) -> 0.99383139
B21: 4 | C21: a | D21: TMR-051 | E21: SLEEVE | K21: 20000 | M21: =AM21*S21/K21 -> 0.0012578616 | N21: =(AN21+AO21)*S21/K21 -> 0.0018 | O21: 0.0002 | P21: PPE+PA | Q21: C82HL | S21: 2 | T21: 31.6 | U21: 16.3 | V21: =T21*S21+U21 -> 79.5 | X21: =ROUNDUP((K21/(1-O21)+AN21+AO21)/S21,0) -> 10012 | Y21: =(X21*V21+AL21)/K21 -> 39.8477 | Z21: 437.8 | AA21: 0.2 | AB21: ='Resin Recycle'!$O$48 -> 57.114983 | AC21: =IF(AA21=0,'Resin Recycle'!$F$40,0) -> 0 | AD21: =(Y21-T21)*AC21/1000 -> 0 | AE21: =Y21*(1-AA21)*Z21/1000+Y21*AA21*AB21/1000+AD21 -> 14.411439 | AF21: 29 | AG21: =AH$5 -> 297.65682 | AH21: =AI$5 -> 543.66751 | AI21: =ROUNDUP(AF21/S21*(AH21+AG21)/(1-N21-O21)/3600,2) -> 3.4 | AL21: 1000 | AM21: =AL21/V21 -> 12.578616 | AN21: 15 | AO21: 3 | AP21: =(AN21+AO21)*V21 -> 1431 | AQ21: 30 | AR21: =IF(C21<1," ",(K21*AF21/S21)/(AQ21*60+K21*AF21/S21)) -> 0.99383139
B22: 5 | C22: a | D22: TMR-051 | E22: MOLDHOLDER 1 | K22: 20000 | M22: =AM22*S22/K22 -> 0.0012578616 | N22: =(AN22+AO22)*S22/K22 -> 0.0018 | O22: 0.0002 | P22: PBT | Q22: BASF B4520 Q120 | S22: 2 | T22: 31.6 | U22: 16.3 | V22: =T22*S22+U22 -> 79.5 | X22: =ROUNDUP((K22/(1-O22)+AN22+AO22)/S22,0) -> 10012 | Y22: =(X22*V22+AL22)/K22 -> 39.8477 | Z22: 437.8 | AA22: 0.2 | AB22: ='Resin Recycle'!$O$48 -> 57.114983 | AC22: =IF(AA22=0,'Resin Recycle'!$F$40,0) -> 0 | AD22: =(Y22-T22)*AC22/1000 -> 0 | AE22: =Y22*(1-AA22)*Z22/1000+Y22*AA22*AB22/1000+AD22 -> 14.411439 | AF22: 28 | AG22: =AH$5 -> 297.65682 | AH22: =AI$5 -> 543.66751 | AI22: =ROUNDUP(AF22/S22*(AH22+AG22)/(1-N22-O22)/3600,2) -> 3.28 | AL22: 1000 | AM22: =AL22/V22 -> 12.578616 | AN22: 15 | AO22: 3 | AP22: =(AN22+AO22)*V22 -> 1431 | AQ22: 30 | AR22: =IF(C22<1," ",(K22*AF22/S22)/(AQ22*60+K22*AF22/S22)) -> 0.99361249
B23: 6 | C23: a | D23: TMR-051 | E23: MOLDHOLDER 2 | K23: 20000 | M23: =AM23*S23/K23 -> 0.0012578616 | N23: =(AN23+AO23)*S23/K23 -> 0.0018 | O23: 0.0002 | P23: PBT | Q23: BASF B4520 Q120 | S23: 2 | T23: 31.6 | U23: 16.3 | V23: =T23*S23+U23 -> 79.5 | X23: =ROUNDUP((K23/(1-O23)+AN23+AO23)/S23,0) -> 10012 | Y23: =(X23*V23+AL23)/K23 -> 39.8477 | Z23: 437.8 | AA23: 0.15 | AB23: ='Resin Recycle'!$O$48 -> 57.114983 | AC23: =IF(AA23=0,'Resin Recycle'!$F$40,0) -> 0 | AD23: =(Y23-T23)*AC23/1000 -> 0 | AE23: =Y23*(1-AA23)*Z23/1000+Y23*AA23*AB23/1000+AD23 -> 15.16991 | AF23: 28 | AG23: =AH$5 -> 297.65682 | AH23: =AI$5 -> 543.66751 | AI23: =ROUNDUP(AF23/S23*(AH23+AG23)/(1-N23-O23)/3600,2) -> 3.28 | AL23: 1000 | AM23: =AL23/V23 -> 12.578616 | AN23: 15 | AO23: 3 | AP23: =(AN23+AO23)*V23 -> 1431 | AQ23: 30 | AR23: =IF(C23<1," ",(K23*AF23/S23)/(AQ23*60+K23*AF23/S23)) -> 0.99361249
B24: 7
B25: 8
B26: 9
B27: 10
B28: 11
B29: 12
B30: 13
B31: 14
B32: 15
AQ33: Stop-Start
B34: Other Direct Cost
B35: =B14 -> QuotationNo. | D35: Anneal Process Cost | H35: Parts Cost （JPY/pcs）
D36: Anneal process | E36: Cost | F36: Defect | G36: Cost | H36: material | I36: process | J36: Direct Cost （JPY/pc)
E38: JPY/pc | F38: Rate (%) | G38: JPY/pc
B39: =B18 -> 1 | D39: YES | E39: 1.7146735 | F39: 0.005 | G39: =E39/(1-F39) -> 1.72329 | H39: =AE18 -> 17.590483 | I39: =G39+AI18 -> 5.24329 | J39: =IF(C18<1," ",H39+I39) -> 22.833773
B40: =B19 -> 2 | D40: YES | E40: 1.7381521 | F40: 0.005 | G40: =E40/(1-F40) -> 1.7468865 | H40: =AE19 -> 17.590483 | I40: =G40+AI19 -> 5.2668865 | J40: =IF(C19<1," ",H40+I40) -> 22.857369 | CB40: 入り数検討
B41: =B20 -> 3 | D41: YES | E41: 4.1306663 | F41: 0.005 | G41: =E41/(1-F41) -> 4.1514234 | H41: =AE20 -> 17.590483 | I41: =G41+AI20 -> 7.5514234 | J41: =IF(C20<1," ",H41+I41) -> 25.141906 | CB41: ポリ内寸 | CC41: 製品 | CD41: 入り数
B42: =B21 -> 4 | D42: NO | E42: 1.6522665 | F42: 0.005 | G42: =E42/(1-F42) -> 1.6605694 | H42: =AE21 -> 14.411439 | I42: =G42+AI21 -> 5.0605694 | J42: =IF(C21<1," ",H42+I42) -> 19.472008 | CB42: 642 | CC42: 100 | CD42: =CB42/CC42 -> 6.42
...

Sheet Sheet2
A3: =30 / 2 * (543.7 + 297.7) / (1 - 0 -0) / 3600 -> 3.5058333

Sheet Resin Recycle (2)
B2: 2. Re-cycle Cost Caliclation
G3: =Anneal!E2 -> 2.2 | H3: JPY/PHP
F4: Electricity Cost | G4: 7 | H4: PHP/kWh | M4: Rate | N4: 319.4 | O4: JPY/hr
C6: Resin | D6: Recycle Machine | E6: Machine Capacity | F6: Electric power Consumption | J6: Total Qty of machine | M6: Man Charge | Q6: FEAP Recycle cost
E7: kg/h-machine | F7: kWh | H7: JPY/hr-machine | J7: machines | K7: JPY/hr | L7: kg/hr | M7: MP | N7: JPY/hr | O7: JPY/hr | Q7: JPY/kg
C8: PBT | E8: 1.8 | F8: 0.75 | H8: =G4*G3*F8 -> 11.55 | J8: 7 | K8: =J8*H8 -> 80.85 | L8: =E8*J8 -> 12.6 | M8: 2 | N8: =M8*N4 -> 638.8 | O8: =K8+N8 -> 719.65 | Q8: =O8/L8 -> 57.115079
Q10: Disposal cost
Q11: PHP/kg
Q12: 8

Sheet Anneal
C1: normal anneal cost
B2: 1 | C2: forex | D2: php | E2: 2.2 | F2: jpy/php
C3: heater capacity | D3: kW | E3: 13.5 | F3: kWh | G3: =E3*0.7 -> 9.45 | H3: *100％は立ち上げのみとみなし、70%の消費電力量とする。
C4: electricity | D4: kW | E4: 7 | F4: php
E5: =E2*G3*E4 -> 145.53 | F5: JPY/hour
B6: 2 | C6: manhour | D6: operator | E6: =MTMH!H5 -> 319.39939 | F6: JPY/hour*man
C7: operator shifting | E7: 5 | F7: man power / shift
E8: 8 | F8: annealing machine
E9: =E6*E7/E8 -> 199.62462 | F9: JPY/hour*machine
C11: electricity on heater | D11: actual time ( including heat up and cool down ) | E11: electricity | F11: manpower | G11: total
C12: [hour]
B13: POM | C13: 4 | D13: 5 | E13: =C13*E5 -> 582.12 | F13: =D13*E9 -> 998.12311 | G13: =E13+F13 -> 1580.2431
B14: PBT | C14: 2 | D14: 3 | E14: =C14*E5 -> 291.06 | F14: =E9*D14 -> 598.87386 | G14: =E14+F14 -> 889.93386
L15: =G13/D16/D17 -> 2469.1299 | M15: =G14/D16/D18 -> 1668.626
B16: 占有率 | C16: occupied | D16: 0.8 | L16: =L15 -> 2469.1299 | M16: =M15 -> 1668.626
B17: OA | C17: POM | D17: =C13/D13 -> 0.8 | L17: =L16 -> 2469.1299 | M17: =M16 -> 1668.626
C18: PBT | D18: =C14/D14 -> 0.66666667 | L18: =L17 -> 2469.1299 | M18: =M17 -> 1668.626
F19: machine in side area | H19: layer | L19: POM | M19: PBT
B20: Size | C20: A | D20: 10 | E20: pcs / tray | F20: 6 | G20: tray /machine | H20: 16 | I20: layer | J20: =D20*F20*H20 -> 960 | L20: =L15/J20 -> 2.5720103 | M20: =M15/J20 -> 1.7381521
C21: B | D21: 12 | E21: pcs / tray | F21: 6 | G21: tray /machine | H21: 16 | I21: layer | J21: =D21*F21*H21 -> 1152 | L21: =L16/J21 -> 2.1433419 | M21: =M16/J21 -> 1.4484601
C22: C | D22: 15 | E22: pcs / tray | F22: 6 | G22: tray /machine | H22: 16 | I22: layer | J22: =D22*F22*H22 -> 1440 | L22: =L17/J22 -> 1.7146735 | M22: =M17/J22 -> 1.1587681
C23: D | D23: 60 | E23: pcs / tray | F23: 6 | G23: tray /machine | H23: 16 | I23: layer | J23: =D23*F23*H23 -> 5760 | L23: =L18/J23 -> 0.42866838 | M23: =M18/J23 -> 0.28969201
C26: water absorption
B27: 1 | C27: forex | D27: php | E27: 2.2 | F27: jpy/php
C28: heater capacity | D28: kW | E28: 13.5 | F28: kWh | G28: =E28*0.7 -> 9.45 | H28: *100％は立ち上げのみとみなし、70%の消費電力量とする。
C29: electricity | D29: kW | E29: 7 | F29: php
E30: =E27*G28*E29 -> 145.53 | F30: JPY/hour
B31: 2 | C31: manhour | D31: operator | E31: =E6 -> 319.39939 | F31: JPY/hour
C32: operator shifting | E32: 5 | F32: man power / shift
E33: 8 | F33: annealing machine
E34: =E31*E32/E33 -> 199.62462 | F34: JPY/hour
C36: electricity on heater | D36: actual time ( including heat up and cool down ) | E36: electricity | F36: manpower | G36: total
C37: [hour]
B38: I | C38: 4 | D38: 5 | E38: =C38*E30 -> 582.12 | F38: =D38*E34 -> 998.12311 | G38: =E38+F38 -> 1580.2431
B39: II | C39: 6 | D39: 7 | E39: =C39*E30 -> 873.18 | F39: =E34*D39 -> 1397.3723 | G39: =E39+F39 -> 2270.5523
B40: III | C40: 8 | D40: 9 | E40: =C40*E30 -> 1164.24 | F40: =E34*D40 -> 1796.6216 | G40: =E40+F40 -> 2960.8616 | L40: =G38/D41/D42 -> 2469.1299 | M40: =G39/D41/D43 -> 3311.2222 | N40: =G40/D41/D44 -> 4163.7116
B41: 占有率 | C41: occupied | D41: 0.8 | L41: =L40 -> 2469.1299 | M41: =M40 -> 3311.2222 | N41: =N40 -> 4163.7116
B42: OA | C42: I | D42: =C38/D38 -> 0.8 | L42: =L41 -> 2469.1299 | M42: =M41 -> 3311.2222 | N42: =N41 -> 4163.7116
C43: II | D43: =C39/D39 -> 0.85714286 | L43: =L42 -> 2469.1299 | M43: =M42 -> 3311.2222 | N43: =N42 -> 4163.7116
C44: III | D44: =C40/D40 -> 0.88888889 | F44: machine in side area | H44: layer | L44: 4h | M44: 5h | N44: 9h
...

Sheet Resin Recycle
B2: 1. Resin Purchasing Price
C4: Resin Name | D4: Color | E4: P/N# | F4: Purchasing Price (original forex) | I4: Purchasing Price (JPY)
C5: BASF ULTRADUR B4520 Q120 | D5: Black | F5: 2.9 | G5: USD | H5: /kg | I5: =IF(G5="USD",F5*$F$28,IF(G5="PHP",F5*$F$29,F5)) -> 304.5 | J5: JPY | K5: /kg
C6: PBT DURANEX 2002 ED | D6: Black | F6: 397.1 | G6: JPY | H6: /kg | I6: =IF(G6="USD",F6*$F$28,IF(G6="PHP",F6*$F$29,F6)) -> 397.1 | J6: JPY | K6: /kg
C7: IUPITAL F30-03 E9000 BLACK | D7: Black | F7: 1.98 | G7: USD | H7: /kg | I7: =IF(G7="USD",F7*$F$28,IF(G7="PHP",F7*$F$29,F7)) -> 207.9 | J7: JPY | K7: /kg
C8: IUPITAL F30-73R1 BLACK | D8: Black | F8: 345.5 | G8: JPY | H8: /kg | I8: =IF(G8="USD",F8*$F$28,IF(G8="PHP",F8*$F$29,F8)) -> 345.5 | J8: JPY | K8: /kg
C9: IUPITAL F30-03 E9003 NATURAL | D9: Natural | F9: 2.03 | G9: USD | H9: /kg | I9: =IF(G9="USD",F9*$F$28,IF(G9="PHP",F9*$F$29,F9)) -> 213.15 | J9: JPY | K9: /kg
C10: IUPITAL FX-11J BLACK | D10: Black | F10: 3.98 | G10: USD | H10: /kg | I10: =IF(G10="USD",F10*$F$28,IF(G10="PHP",F10*$F$29,F10)) -> 417.9 | J10: JPY | K10: /kg
C11: DURACON NW-02 BLACK | D11: Black | F11: 4.7 | G11: USD | H11: /kg | I11: =IF(G11="USD",F11*$F$28,IF(G11="PHP",F11*$F$29,F11)) -> 493.5 | J11: JPY | K11: /kg
C12: IUPITAL F20-73R1 BLUE | D12: Blue | F12: 1623.68 | G12: JPY | H12: /kg | I12: =IF(G12="USD",F12*$F$28,IF(G12="PHP",F12*$F$29,F12)) -> 1623.68 | J12: JPY | K12: /kg
C13: IUPITAL F30-73R1 NATURAL | D13: Natural | F13: 345.5 | G13: JPY | H13: /kg | I13: =IF(G13="USD",F13*$F$28,IF(G13="PHP",F13*$F$29,F13)) -> 345.5 | J13: JPY | K13: /kg
C14: POM IUPITAL F30-03, FOP 3CA030 ORG | D14: Orange | F14: 3.15 | G14: USD | H14: /kg | I14: =IF(G14="USD",F14*$F$28,IF(G14="PHP",F14*$F$29,F14)) -> 330.75 | J14: JPY | K14: /kg
C15: POLYBUTYL TERAPTHALATE BASF | F15: 2.9 | G15: USD | H15: /kg | I15: =IF(G15="USD",F15*$F$28,IF(G15="PHP",F15*$F$29,F15)) -> 304.5 | J15: JPY | K15: /kg
C16: ULTRADUR B4520 | D16: Green | F16: 6.652 | G16: USD | H16: /kg | I16: =IF(G16="USD",F16*$F$28,IF(G16="PHP",F16*$F$29,F16)) -> 698.46 | J16: JPY | K16: /kg
C17: PBT PB-25K | D17: Black | F17: 1494.07 | G17: JPY | H17: /kg | I17: =IF(G17="USD",F17*$F$28,IF(G17="PHP",F17*$F$29,F17)) -> 1494.07 | J17: JPY | K17: /kg
C18: PBT 1401-X34 | F18: 343.23 | G18: JPY | H18: /kg | I18: =IF(G18="USD",F18*$F$28,IF(G18="PHP",F18*$F$29,F18)) -> 343.23 | J18: JPY | K18: /kg
C19: POM IUPITAL F30-03, FOP 2CA087 YEL | D19: Yellow | F19: 3.7 | G19: USD | H19: /kg | I19: =IF(G19="USD",F19*$F$28,IF(G19="PHP",F19*$F$29,F19)) -> 388.5 | J19: JPY | K19: /kg
C20: POM IUPITAL F30-03, FOP 7CA311 BLU | D20: Blue | F20: 3.7 | G20: USD | H20: /kg | I20: =IF(G20="USD",F20*$F$28,IF(G20="PHP",F20*$F$29,F20)) -> 388.5 | J20: JPY | K20: /kg
C21: POM IUPITAL F30-03, FOP 5CA120 GRN | D21: Green | F21: 3.87 | G21: USD | H21: /kg | I21: =IF(G21="USD",F21*$F$28,IF(G21="PHP",F21*$F$29,F21)) -> 406.35 | J21: JPY | K21: /kg
C22: POM IUPITAL F30-03, FOP 3CA030 ORG | D22: Orange | F22: 3.87 | G22: USD | H22: /kg | I22: =IF(G22="USD",F22*$F$28,IF(G22="PHP",F22*$F$29,F22)) -> 406.35 | J22: JPY | K22: /kg
C23: PPS DIC FZ-1140K | F23: 736.5 | G23: JPY | H23: /kg | I23: =IF(G23="USD",F23*$F$28,IF(G23="PHP",F23*$F$29,F23)) -> 736.5 | J23: JPY | K23: /kg
C24: PPS DIC FZ-1040K | F24: 776.9 | G24: JPY | H24: /kg | I24: =IF(G24="USD",F24*$F$28,IF(G24="PHP",F24*$F$29,F24)) -> 776.9 | J24: JPY | K24: /kg
C25: PP J715M | D25: Natural | F25: 2.325 | G25: USD | H25: /kg | I25: =IF(G25="USD",F25*$F$28,IF(G25="PHP",F25*$F$29,F25)) -> 244.125 | J25: JPY | K25: /kg
C26: PP master batch | D26: Blue | F26: 366 | G26: PHP | H26: /kg | I26: =IF(G26="USD",F26*$F$28,IF(G26="PHP",F26*$F$29,F26)) -> 805.2 | J26: JPY | K26: /kg
C28: FOREX ; | F28: 105 | G28: JPY/USD
F29: 2.2 | G29: JPY/PHP
B31: 2. Re-cycle Cost Caliclation
C33: Resin | D33: Recycle machine | F33: Electric power consumption
F34: 0.75 | G34: kWh
C39: Recycle cost | F39: =O48 -> 57.114983 | G39: JPY/h-kg
C40: Disporsal cost | F40: 17.6 | G40: JPY/kg | H40: Virgin material need to add disporsal cost /バージン材は廃却コストを加算する。
C42: Recycle Material Cost | F42: リサイクルコスト
B43: 為替 | C43: Forex | E43: =Anneal!E2 -> 2.2 | F43: JPY/PHP | G43: Electricity
B44: 電気代 | C44: Electricity | E44: 0.75 | F44: kWh | G44: 7 | H44: PHP/kWh | I44: =E44*G44*E43 -> 11.55 | J44: JPY/h-machine | M44: 7 | N44: machine | O44: =I44*M44 -> 80.85 | P44: JPY/h
B45: 人件費 | C45: Manhour | E45: 1 | F45: operator | G45: =Anneal!E6 -> 319.39939 | H45: JPY/h | I45: =G45 -> 319.39939 | J45: JPY/h-man | M45: 2 | N45: operator | O45: =M45*I45 -> 638.79879 | P45: JPY/h
N46: Total | O46: =O44+O45 -> 719.64879 | P46: JPY/h
B47: 処理能力 | C47: Machine Capability | E47: 1.8 | F47: kg/h | G47: /machine | O47: =E47*M44 -> 12.6 | P47: kg/h
O48: =O46/O47 -> 57.114983 | P48: JPY/h-kg
E50: Disporsal cost | F50: 8 | G50: PHP/kg

Sheet MTMH
F3: =1/F4 -> 2.1299255 | H3: hourly | I3: 2018 | J3: 2019 | K3: 20 | L3: 21 | M3: 22 | N3: 23 | O3: 24 | P3: 25 | Q3: 26 | R3: 27 | S3: 28 | T3: 29 | U3: 30 | V3: 31
C4: FEAP | D4: OPERATOR | E4: 1004.1803 | F4: 0.4695 | G4: =E4/F4 -> 2138.8291 | H4: =G4/8 -> 267.35364 | I4: =H4*1.25 -> 334.19205 | J4: =I4*1.05 -> 350.90165 | K4: =J4*1.05 -> 368.44673 | L4: =K4*1.05 -> 386.86907 | M4: =L4*1.05 -> 406.21252 | N4: =M4*1.05 -> 426.52315 | O4: =N4*1.05 -> 447.8493 | P4: =O4*1.05 -> 470.24177 | Q4: =P4*1.05 -> 493.75386 | ... V4: =U4*1.05 -> 630.16894
D5: SUB LEADER | E5: 1199.6641 | F5: 0.4695 | G5: =E5/F5 -> 2555.1952 | H5: =G5/8 -> 319.39939 | J5: =AVERAGE(M4:Q4) -> 448.91612
D6: TEAM LEADER | E6: 1291.7479 | F6: 0.4695 | G6: =E6/F6 -> 2751.3268 | H6: =G6/8 -> 343.91585
D7: CONTROLLER | E7: 1125.6196 | F7: 0.4695 | G7: =E7/F7 -> 2397.4858 | H7: =G7/8 -> 299.68572
D8: INSPECTOR | E8: 939.91451 | F8: 0.4695 | G8: =E8/F8 -> 2001.9478 | H8: =G8/8 -> 250.24348
C9: agency | D9: ALL POSITION | E9: 544.75968 | F9: 0.4695 | G9: =E9/F9 -> 1160.2975 | H9: =G9/8 -> 145.03719
C14: 2017 | D14: 2018 | E14: 2019 | F14: 20 | G14: 21 | H14: 22 | I14: 23 | J14: 24 | K14: 25 | L14: 26 | M14: 27 | N14: 28
A15: hori | B15: MH | C15: 176.163 | D15: =C15*1.25 -> 220.20375 | E15: 297.65682 | F15: =E15*1.05 -> 312.53966 | G15: =F15*1.05 -> 328.16665 | H15: =G15*1.05 -> 344.57498 | I15: =H15*1.05 -> 361.80373 | J15: =I15*1.05 -> 379.89392 | K15: =J15*1.05 -> 398.88861 | L15: =K15*1.05 -> 418.83304 | M15: =L15*1.05 -> 439.77469 | N15: =M15*1.05 -> 461.76343
A16: hori | B16: MT | C16: 565.3723 | D16: =C16*1.02 -> 576.67975 | E16: 543.66751 | F16: =E16*1.02 -> 554.54086 | G16: =F16*1.02 -> 565.63168 | H16: =G16*1.02 -> 576.94431 | I16: =H16*1.02 -> 588.4832 | J16: =I16*1.02 -> 600.25286 | K16: =J16*1.02 -> 612.25792 | L16: =K16*1.02 -> 624.50308 | M16: =L16*1.02 -> 636.99314 | N16: =M16*1.02 -> 649.733
A17: vertical | B17: MT | C17: 655.44094 | D17: =C17*1.02 -> 668.54976 | E17: =D17*1.02 -> 681.92075 | F17: =E17*1.02 -> 695.55917 | G17: =F17*1.02 -> 709.47035 | H17: =G17*1.02 -> 723.65976 | I17: =H17*1.02 -> 738.13296 | J17: =I17*1.02 -> 752.89561 | K17: =J17*1.02 -> 767.95353 | ... N17: =M17*1.02 -> 814.95843
E18: =AVERAGE(H15:K15) -> 371.29031
E19: =AVERAGE(H16:K16) -> 594.48457
E20: =AVERAGE(H17:K17) -> 745.66046
E22: 2019年用の値
E23: Verticalは未計算
E26: 1162.1903
